## panic!

### 简介

panic用于处理那些不可恢复的错误（越界等）

有两种方法造成 panic：执行会造成代码 panic 的操作（比如访问超过数组结尾的内容）或者显式调用 `panic!` 宏

通常情况下这些 panic 会打印出一个错误信息，展开并清理栈数据，然后退出。通过一个环境变量，也可以让 Rust 在 panic 发生时打印调用堆栈（call stack）以便于定位 panic 的原因

>当出现 panic 时，程序默认会开始 **展开**（_unwinding_），这意味着 Rust 会回溯栈并清理它遇到的每一个函数的数据，不过这个回溯并清理的过程有很多工作。另一种选择是直接 **终止**（_abort_），这会不清理数据就退出程序。那么程序所使用的内存需要由操作系统来清理。如果你需要项目的最终二进制文件越小越好，panic 时通过在 _Cargo.toml_ 的 `[profile]` 部分增加 `panic = 'abort'`，可以由展开切换为终止。例如，如果你想要在 release 模式中 panic 时直接终止：`[profile.release] panic = 'abort'`

### 使用

```rust
fn main() { 
	panic!("crash and burn"); 
}
```

在其他情况下，`panic!` 可能会出现在我们的代码所调用的代码中。错误信息报告的文件名和行号可能指向别人代码中的 `panic!` 宏调用，而不是我们代码中最终导致 `panic!` 的那一行。我们可以使用 `panic!` 被调用的函数的 backtrace 来寻找代码中出问题的地方

**panic 的 backtrace**

```rust
fn main() {
    let v = vec![1, 2, 3];

    v[99];
}
```

_backtrace_ 是一个执行到目前位置所有被调用的函数的列表

在运行时设置 `RUST_BACKTRACE=1 cargo run` 可以获取 `backtrace` 信息

## Result枚举

### 简介

大部分错误并没有严重到需要程序完全停止执行。有时，一个函数会因为一个容易理解并做出反应的原因失败。例如，如果因为打开一个并不存在的文件而失败，此时我们可能想要创建这个文件，而不是终止进程

### 基本使用

```rust
use std::fs::File;
  
fn main() {
	let greeting_file_result = File::open("hello.txt");
	
	let greeting_file = match greeting_file_result {
		Ok(file) => file,
		Err(error) => panic!("Problem opening the file: {:?}", error),
	};
}
```

`File::open` 的返回值是 `Result<T, E>`

**注意:** 与 `Option` 枚举一样，`Result` 枚举和其成员也被导入到了 prelude 中，所以就不需要在 `match` 分支中的 `Ok` 和 `Err` 之前指定 `Result::`

### 匹配不同错误

```rust
use std::fs::File;
use std::io::ErrorKind;

fn main() {
    let greeting_file_result = File::open("hello.txt");

    let greeting_file = match greeting_file_result {
        Ok(file) => file,
        Err(error) => match error.kind() {
            ErrorKind::NotFound => match File::create("hello.txt") { // 没有就创建
                Ok(fc) => fc,
                Err(e) => panic!("Problem creating the file: {:?}", e),
            },
            other_error => {
                panic!("Problem opening the file: {:?}", other_error);
            }
        },
    };
}
```

当然，上述代码也可以使用 `if let else` 实现

```rust
use std::fs::File;
use std::io::ErrorKind;

fn main() {
    let greeting_file = File::open("hello.txt").unwrap_or_else(|error| {
        if error.kind() == ErrorKind::NotFound {
            File::create("hello.txt").unwrap_or_else(|error| {
                panic!("Problem creating the file: {:?}", error);
            })
        } else {
            panic!("Problem opening the file: {:?}", error);
        }
    });
}
```


### 失败时 panic 的简写：`unwrap` 和 `expect`

`Result<T, E>` 类型定义了很多辅助方法来处理各种情况。其中之一叫做 `unwrap`。如果 `Result` 值是成员 `Ok`，`unwrap` 会返回 `Ok` 中的值。如果 `Result` 是成员 `Err`，`unwrap` 会为我们调用 `panic!`

```rust
use std::fs::File;

fn main() {
    let greeting_file = File::open("hello.txt").unwrap();
}
```

还有另一个类似于 `unwrap` 的方法它还允许我们选择 `panic!` 的错误信息：`expect`。使用 `expect` 而不是 `unwrap` 并提供一个好的错误信息可以表明你的意图并更易于追踪 panic 的根源

```rust
use std::fs::File;

fn main() {
    let greeting_file = File::open("hello.txt")
        .expect("hello.txt should be included in this project");
}
```

`expect` 与 `unwrap` 的使用方式一样：返回文件句柄或调用 `panic!` 宏。`expect` 在调用 `panic!` 时使用的错误信息将是我们传递给 `expect` 的参数，而不像 `unwrap` 那样使用默认的 `panic!` 信息

### 传播错误

当编写一个其实先会调用一些可能会失败的操作的函数时，除了在这个函数中处理错误外，还可以选择让调用者知道这个错误并决定该如何处理。这被称为 **传播**（_propagating_）错误

```rust
#![allow(unused)]
fn main() {
	use std::fs::File;
	use std::io::{self, Read};
	
	fn read_username_from_file() -> Result<String, io::Error> {
	    let username_file_result = File::open("hello.txt");
	
	    let mut username_file = match username_file_result {
	        Ok(file) => file,
	        Err(e) => return Err(e),
	    };
	
	    let mut username = String::new();
	
	    match username_file.read_to_string(&mut username) {
	        Ok(_) => Ok(username),
	        Err(e) => Err(e),
	    }
	}
}
```

对于一个模式匹配

```rust
let username_file_result = File::open("hello.txt");

let mut username_file = match username_file_result {
	Ok(file) => file,
	Err(e) => return Err(e),
};
```

由于我们需要的是获取`Ok(arg)`中`arg`的值，如果发生错误就返回`err`，那么有语法糖 `?` 代替

上述代码可以简化为

```rust
let mut username_file = File::open("hello.txt")?;
```

所以对于上述的代码可以化简为如下

```rust
#![allow(unused)]
fn main() {
	use std::fs::File;
	use std::io::{self, Read};
	
	fn read_username_from_file() -> Result<String, io::Error> {
	    let mut username_file = File::open("hello.txt")?;
	    let mut username = String::new();
	    username_file.read_to_string(&mut username)?;
	    Ok(username)
	}
}
```

当然也可以直接使用链式调用

```rust
#![allow(unused)]
fn main() {
	use std::fs::File;
	use std::io::{self, Read};
	
	fn read_username_from_file() -> Result<String, io::Error> {
		let mut username = String::new();  
		File::open("hello.txt")?.read_to_string(&mut username)?;
		Ok(username)
	}
}
```

当程序遇到 `?` 运算符，会自行的调用 `from` 函数，来转化错误类型为函数返回值标明的错误类型（当然不是所有错误类型之间都可以相互转换）

**注意：** `?` 运算符只能被用于返回值与 `?` 作用的值相兼容的函数（如上所述），也就是说函数的返回值必须符合 `?` 提前返回的分支才可以使用




